{"name": "The user should be able to view orders repository", "status": "broken", "statusDetails": {"message": "urllib3.exceptions.MaxRetryError: HTTPConnectionPool(host='localhost', port=51544): Max retries exceeded with url: /session/ab085b02aeb9f1b32d708871c51d87bf/screenshot (Caused by NewConnectionError('<urllib3.connection.HTTPConnection object at 0x000001E0DA0FF9D0>: Failed to establish a new connection: [WinError 10061] No connection could be made because the target machine actively refused it'))\n", "trace": "  File \"C:\\Users\\akankshyad\\AppData\\Local\\Programs\\Python\\Python310\\lib\\site-packages\\behave\\runner.py\", line 545, in run_hook\n    self.hooks[name](context, *args)\n  File \"Features\\environment.py\", line 75, in after_step\n    allure.attach(context.driver.get_screenshot_as_png(), name=\"screenshot\", attachment_type=AttachmentType.PNG)\n  File \"C:\\Users\\akankshyad\\AppData\\Local\\Programs\\Python\\Python310\\lib\\site-packages\\selenium\\webdriver\\remote\\webdriver.py\", line 965, in get_screenshot_as_png\n    return b64decode(self.get_screenshot_as_base64().encode(\"ascii\"))\n  File \"C:\\Users\\akankshyad\\AppData\\Local\\Programs\\Python\\Python310\\lib\\site-packages\\selenium\\webdriver\\remote\\webdriver.py\", line 977, in get_screenshot_as_base64\n    return self.execute(Command.SCREENSHOT)[\"value\"]\n  File \"C:\\Users\\akankshyad\\AppData\\Local\\Programs\\Python\\Python310\\lib\\site-packages\\selenium\\webdriver\\remote\\webdriver.py\", line 442, in execute\n    response = self.command_executor.execute(driver_command, params)\n  File \"C:\\Users\\akankshyad\\AppData\\Local\\Programs\\Python\\Python310\\lib\\site-packages\\selenium\\webdriver\\remote\\remote_connection.py\", line 294, in execute\n    return self._request(command_info[0], url, body=data)\n  File \"C:\\Users\\akankshyad\\AppData\\Local\\Programs\\Python\\Python310\\lib\\site-packages\\selenium\\webdriver\\remote\\remote_connection.py\", line 316, in _request\n    response = self._conn.request(method, url, body=body, headers=headers)\n  File \"C:\\Users\\akankshyad\\AppData\\Local\\Programs\\Python\\Python310\\lib\\site-packages\\urllib3\\request.py\", line 74, in request\n    return self.request_encode_url(\n  File \"C:\\Users\\akankshyad\\AppData\\Local\\Programs\\Python\\Python310\\lib\\site-packages\\urllib3\\request.py\", line 96, in request_encode_url\n    return self.urlopen(method, url, **extra_kw)\n  File \"C:\\Users\\akankshyad\\AppData\\Local\\Programs\\Python\\Python310\\lib\\site-packages\\urllib3\\poolmanager.py\", line 376, in urlopen\n    response = conn.urlopen(method, u.request_uri, **kw)\n  File \"C:\\Users\\akankshyad\\AppData\\Local\\Programs\\Python\\Python310\\lib\\site-packages\\urllib3\\connectionpool.py\", line 826, in urlopen\n    return self.urlopen(\n  File \"C:\\Users\\akankshyad\\AppData\\Local\\Programs\\Python\\Python310\\lib\\site-packages\\urllib3\\connectionpool.py\", line 826, in urlopen\n    return self.urlopen(\n  File \"C:\\Users\\akankshyad\\AppData\\Local\\Programs\\Python\\Python310\\lib\\site-packages\\urllib3\\connectionpool.py\", line 826, in urlopen\n    return self.urlopen(\n  File \"C:\\Users\\akankshyad\\AppData\\Local\\Programs\\Python\\Python310\\lib\\site-packages\\urllib3\\connectionpool.py\", line 798, in urlopen\n    retries = retries.increment(\n  File \"C:\\Users\\akankshyad\\AppData\\Local\\Programs\\Python\\Python310\\lib\\site-packages\\urllib3\\util\\retry.py\", line 592, in increment\n    raise MaxRetryError(_pool, url, error or ResponseError(cause))\n"}, "steps": [{"name": "And Scroll through menu to view planning option", "status": "broken", "statusDetails": {"message": "urllib3.exceptions.MaxRetryError: HTTPConnectionPool(host='localhost', port=51544): Max retries exceeded with url: /session/ab085b02aeb9f1b32d708871c51d87bf/screenshot (Caused by NewConnectionError('<urllib3.connection.HTTPConnection object at 0x000001E0DA0FF9D0>: Failed to establish a new connection: [WinError 10061] No connection could be made because the target machine actively refused it'))\n", "trace": "  File \"C:\\Users\\akankshyad\\AppData\\Local\\Programs\\Python\\Python310\\lib\\site-packages\\behave\\runner.py\", line 545, in run_hook\n    self.hooks[name](context, *args)\n  File \"Features\\environment.py\", line 75, in after_step\n    allure.attach(context.driver.get_screenshot_as_png(), name=\"screenshot\", attachment_type=AttachmentType.PNG)\n  File \"C:\\Users\\akankshyad\\AppData\\Local\\Programs\\Python\\Python310\\lib\\site-packages\\selenium\\webdriver\\remote\\webdriver.py\", line 965, in get_screenshot_as_png\n    return b64decode(self.get_screenshot_as_base64().encode(\"ascii\"))\n  File \"C:\\Users\\akankshyad\\AppData\\Local\\Programs\\Python\\Python310\\lib\\site-packages\\selenium\\webdriver\\remote\\webdriver.py\", line 977, in get_screenshot_as_base64\n    return self.execute(Command.SCREENSHOT)[\"value\"]\n  File \"C:\\Users\\akankshyad\\AppData\\Local\\Programs\\Python\\Python310\\lib\\site-packages\\selenium\\webdriver\\remote\\webdriver.py\", line 442, in execute\n    response = self.command_executor.execute(driver_command, params)\n  File \"C:\\Users\\akankshyad\\AppData\\Local\\Programs\\Python\\Python310\\lib\\site-packages\\selenium\\webdriver\\remote\\remote_connection.py\", line 294, in execute\n    return self._request(command_info[0], url, body=data)\n  File \"C:\\Users\\akankshyad\\AppData\\Local\\Programs\\Python\\Python310\\lib\\site-packages\\selenium\\webdriver\\remote\\remote_connection.py\", line 316, in _request\n    response = self._conn.request(method, url, body=body, headers=headers)\n  File \"C:\\Users\\akankshyad\\AppData\\Local\\Programs\\Python\\Python310\\lib\\site-packages\\urllib3\\request.py\", line 74, in request\n    return self.request_encode_url(\n  File \"C:\\Users\\akankshyad\\AppData\\Local\\Programs\\Python\\Python310\\lib\\site-packages\\urllib3\\request.py\", line 96, in request_encode_url\n    return self.urlopen(method, url, **extra_kw)\n  File \"C:\\Users\\akankshyad\\AppData\\Local\\Programs\\Python\\Python310\\lib\\site-packages\\urllib3\\poolmanager.py\", line 376, in urlopen\n    response = conn.urlopen(method, u.request_uri, **kw)\n  File \"C:\\Users\\akankshyad\\AppData\\Local\\Programs\\Python\\Python310\\lib\\site-packages\\urllib3\\connectionpool.py\", line 826, in urlopen\n    return self.urlopen(\n  File \"C:\\Users\\akankshyad\\AppData\\Local\\Programs\\Python\\Python310\\lib\\site-packages\\urllib3\\connectionpool.py\", line 826, in urlopen\n    return self.urlopen(\n  File \"C:\\Users\\akankshyad\\AppData\\Local\\Programs\\Python\\Python310\\lib\\site-packages\\urllib3\\connectionpool.py\", line 826, in urlopen\n    return self.urlopen(\n  File \"C:\\Users\\akankshyad\\AppData\\Local\\Programs\\Python\\Python310\\lib\\site-packages\\urllib3\\connectionpool.py\", line 798, in urlopen\n    retries = retries.increment(\n  File \"C:\\Users\\akankshyad\\AppData\\Local\\Programs\\Python\\Python310\\lib\\site-packages\\urllib3\\util\\retry.py\", line 592, in increment\n    raise MaxRetryError(_pool, url, error or ResponseError(cause))\n"}, "start": 1717046428576, "stop": 1717046446197}, {"name": "And Scroll through menu to view orders menu", "status": "skipped", "start": 1717046446198, "stop": 1717046446198}, {"name": "And Click on orders button", "status": "skipped", "start": 1717046446198, "stop": 1717046446198}], "start": 1717046427568, "stop": 1717046446198, "uuid": "bf2330d7-a9a0-4d7b-a583-d4e20ef9257a", "historyId": "8861ba84460d4043a237208c15b1b0a1", "fullName": "Verify the TMS functionality: The user should be able to view orders repository", "labels": [{"name": "severity", "value": "normal"}, {"name": "tag", "value": "Orders"}, {"name": "feature", "value": "Verify the TMS functionality"}, {"name": "framework", "value": "behave"}, {"name": "language", "value": "cpython3"}]}